<?xml version="1.0" ?>
<mujoco model="hinge0">
    <compiler angle="radian" coordinate="local"/>
    <option timestep="0.002" iterations="100" integrator="Euler" cone="pyramidal" jacobian="dense" solver="Newton">
        <flag sensornoise="enable"/>
    </option>
    <size nconmax="-1" njmax="-1" nuserdata="100"/>
    <asset>
        <mesh name="mesh_PWP_mesh" file="mesh_stl/PWP_mesh.stl"/>
        <mesh name="mesh_Ax2_mesh" file="mesh_stl/Ax2_mesh.stl"/>
    </asset>
    <worldbody>
        <body name="PWP" pos="0.0 0.0 0.0" quat="0.9968165755271912 -0.03723352402448654 0.07046739757061005 -0.0021869433112442493">
            <geom name="PWP" type="mesh" pos="0 0 0" quat="1 0 0 0" rgba="0.23672924935817719 0.4504440128803253 0.8000000715255737 1.0" mass="1.0" contype="1" conaffinity="1" mesh="mesh_PWP_mesh"/>
            <body name="Ax2" pos="-0.6656235456466675 -0.25637999176979065 2.696373462677002" quat="0.9299699664115906 -0.2218094915151596 -0.29271209239959717 0.016616662964224815">
                <geom name="Ax2" type="mesh" pos="0 0 0" quat="1 0 0 0" rgba="0.8000000715255737 0.34003177285194397 0.06936763226985931 1.0" mass="1.0" contype="1" conaffinity="1" mesh="mesh_Ax2_mesh"/>
                <joint name="pwp_ax2_joint" type="hinge" axis="0.42408114671707153 0.6837401390075684 0.22121603786945343" pos="-0.3040509819984436 -0.17807425558567047 -0.4642482101917267" stiffness="0.0" damping="0.0" springref="0.0" limited="false"/>
            </body>
        </body>
        <geom name="floor" type="plane" size="4.930455207824707 3.646454334259033 0.009999999776482582 " pos="0.0 0.0 0.0" quat="1.0 0.0 0.0 0.0" mass="1.0" rgba="0.5 0.5 0.5 0.1" contype="1" conaffinity="1"/>
        <light directional="true" cutoff="4" exponent="20" diffuse="1 1 1" specular="0 0 0" pos="0.9 0.3 2.5" dir="-0.9 -0.3 -2.5"/>
    </worldbody>
    <contact>
        <exclude body1="PWP" body2="Ax2"/>
    </contact>
    <actuator/>
    <equality/>
    <sensor/>
</mujoco>
