<?xml version="1.0" ?>
<mujoco model="basic_demo1">
    <compiler angle="radian" coordinate="local"/>
    <option timestep="0.002" iterations="100" integrator="Euler" cone="pyramidal" jacobian="dense" solver="Newton">
        <flag sensornoise="enable"/>
    </option>
    <size nconmax="-1" njmax="-1" nuserdata="100"/>
    <asset>
        <mesh name="mesh_red_box_mesh" file="mesh_stl/red_box_mesh.stl"/>
        <mesh name="mesh_green_sphere_mesh" file="mesh_stl/green_sphere_mesh.stl"/>
    </asset>
    <worldbody>
        <body name="red_box" pos="0.0 0.0 0.0" quat="0.965925931930542 0.0 0.0 0.2588190734386444">
            <geom name="red_box" type="mesh" pos="0 0 0" quat="1 0 0 0" rgba="1.0 0.0011856346391141415 0.0 1.0" mass="1.0" contype="1" conaffinity="1" mesh="mesh_red_box_mesh"/>
            <body name="green_sphere" pos="1.0 1.0 1.0" quat="1.0 0.0 0.0 0.0">
                <geom name="green_sphere" type="mesh" pos="0 0 0" quat="1 0 0 0" rgba="0.009210149757564068 1.0 0.005964972078800201 1.0" mass="1.0" contype="1" conaffinity="1" mesh="mesh_green_sphere_mesh"/>
            </body>
            <joint name="swing" type="hinge" axis="0.5 0.8660253882408142 0.0" pos="-1.366025447845459 -0.3660253882408142 -1.0" stiffness="0.0" damping="0.0" springref="0.0" limited="false"/>
        </body>
        <light directional="true" cutoff="4" exponent="20" diffuse="1 1 1" specular="0 0 0" pos="0.9 0.3 2.5" dir="-0.9 -0.3 -2.5"/>
    </worldbody>
    <actuator/>
    <equality/>
    <sensor/>
</mujoco>
